Workbook

Sheet Historical Data
A1: Greenfield Pharma Ltd – Historical Financial Data
A3: Particulars | B3: 2020 | C3: 2021 | D3: 2022 | E3: 2023 | F3: 2024
A4: Revenue | B4: 42000 | C4: 46000 | D4: 51000 | E4: 57000 | F4: 64000
A5: Operating expenses | B5: 29000 | C5: 31500 | D5: 34500 | E5: 38000 | F5: 42500
A6: Depriciation | B6: 1800 | C6: 1900 | D6: 2100 | E6: 2300 | F6: 2500
A7: Intrest | B7: 300 | C7: 300 | D7: 320 | E7: 350 | F7: 380
A8: Tax Rate | B8: 0.25 | C8: 0.25 | D8: 0.25 | E8: 0.25 | F8: 0.25
A10: EBITA | B10: =B4-B5 -> 13000 | C10: =C4-C5 -> 14500 | D10: =D4-D5 -> 16500 | E10: =E4-E5 -> 19000 | F10: =F4-F5 -> 21500
A11: EBIT | B11: =B10-B6 -> 11200 | C11: =C10-C6 -> 12600 | D11: =D10-D6 -> 14400 | E11: =E10-E6 -> 16700 | F11: =F10-F6 -> 19000
A12: PBT | B12: =B11-B7 -> 10900 | C12: =C11-C7 -> 12300 | D12: =D11-D7 -> 14080 | E12: =E11-E7 -> 16350 | F12: =F11-F7 -> 18620
A13: Tax | B13: =B12*B8 -> 2725 | C13: =C12*C8 -> 3075 | D13: =D12*D8 -> 3520 | E13: =E12*E8 -> 4087.5 | F13: =F12*F8 -> 4655
A14: Net Income | B14: =B12-B13 -> 8175 | C14: =C12-C13 -> 9225 | D14: =D12-D13 -> 10560 | E14: =E12-E13 -> 12262.5 | F14: =F12-F13 -> 13965
A16: BALANCE SHEET
A17: Particulars | B17: 2020 | C17: 2021 | D17: 2022 | E17: 2023 | F17: 2024
A18: Total Asset | B18: 55000 | C18: 60000 | D18: 66000 | E18: 73000 | F18: 81000
A19: Total Debt | B19: 8000 | C19: 8500 | D19: 9000 | E19: 9500 | F19: 10000
A20: Cash | B20: 6000 | C20: 7200 | D20: 8500 | E20: 10000 | F20: 11800
A21: Equity | B21: 44000 | C21: 48500 | D21: 53500 | E21: 59500 | F21: 66500
A23: ADDITIONAL INFORMATION
A24: Risk Free Rate | B24: 0.06
A25: Market Return | B25: 0.12
A26: Equity Beta | B26: 0.85
A27: Cost of Debt | B27: 0.07
A28: Outstanding Share | B28: 160
A29: Expected Growth Rate | B29: 0.07
A31: EBITA Margin | B31: =B10/B4 -> 0.30952381 | C31: =C10/C4 -> 0.31521739 | D31: =D10/D4 -> 0.32352941 | E31: =E10/E4 -> 0.33333333 | F31: =F10/F4 -> 0.3359375
A32: EBIT Margin | B32: =B11/B4 -> 0.26666667 | C32: =C11/C4 -> 0.27391304 | D32: =D11/D4 -> 0.28235294 | E32: =E11/E4 -> 0.29298246 | F32: =F11/F4 -> 0.296875
A33: Net Profit Margin | B33: =B14/B4 -> 0.19464286 | C33: =C14/C4 -> 0.20054348 | D33: =D14/D4 -> 0.20705882 | E33: =E14/E4 -> 0.21513158 | F33: =F14/F4 -> 0.21820312
A34: Revenue Growth | B34: N/A | C34: =C4/B4-1 -> 0.095238095 | D34: =D4/C4-1 -> 0.10869565 | E34: =E4/D4-1 -> 0.11764706 | F34: =F4/E4-1 -> 0.12280702
A35: Net Income Growth | B35: N/A | C35: =C14/B14-1 -> 0.12844037 | D35: =D14/C14-1 -> 0.14471545 | E35: =E14/D14-1 -> 0.16122159 | F35: =F14/E14-1 -> 0.13883792

Sheet Financial Analysis
A1: Greenfield Pharma Ltd – Financial Analysis
A3: Common-Size Income Statement
A4: Particulars | B4: 2020 | C4: 2021 | D4: 2022 | E4: 2023 | F4: 2024
A5: Revenue | B5: ='Historical Data'!B4/'Historical Data'!B4 -> 1 | C5: ='Historical Data'!C4/'Historical Data'!C4 -> 1 | D5: ='Historical Data'!D4/'Historical Data'!D4 -> 1 | E5: ='Historical Data'!E4/'Historical Data'!E4 -> 1 | F5: ='Historical Data'!F4/'Historical Data'!F4 -> 1
A6: Operating Expenses | B6: ='Historical Data'!B5/'Historical Data'!B4 -> 0.69047619 | C6: ='Historical Data'!C5/'Historical Data'!C4 -> 0.68478261 | D6: ='Historical Data'!D5/'Historical Data'!D4 -> 0.67647059 | E6: ='Historical Data'!E5/'Historical Data'!E4 -> 0.66666667 | F6: ='Historical Data'!F5/'Historical Data'!F4 -> 0.6640625
A7: Depriciation | B7: ='Historical Data'!B6/'Historical Data'!B4 -> 0.042857143 | C7: ='Historical Data'!C6/'Historical Data'!C4 -> 0.041304348 | D7: ='Historical Data'!D6/'Historical Data'!D4 -> 0.041176471 | E7: ='Historical Data'!E6/'Historical Data'!E4 -> 0.040350877 | F7: ='Historical Data'!F6/'Historical Data'!F4 -> 0.0390625
A8: Intrest | B8: ='Historical Data'!B7/'Historical Data'!B4 -> 0.0071428571 | C8: ='Historical Data'!C7/'Historical Data'!C4 -> 0.0065217391 | D8: ='Historical Data'!D7/'Historical Data'!D4 -> 0.0062745098 | E8: ='Historical Data'!E7/'Historical Data'!E4 -> 0.0061403509 | F8: ='Historical Data'!F7/'Historical Data'!F4 -> 0.0059375
A9: EBITA | B9: ='Historical Data'!B10/'Historical Data'!B4 -> 0.30952381 | C9: ='Historical Data'!C10/'Historical Data'!C4 -> 0.31521739 | D9: ='Historical Data'!D10/'Historical Data'!D4 -> 0.32352941 | E9: ='Historical Data'!E10/'Historical Data'!E4 -> 0.33333333 | F9: ='Historical Data'!F10/'Historical Data'!F4 -> 0.3359375
A10: EBITA | B10: ='Historical Data'!B11/'Historical Data'!B4 -> 0.26666667 | C10: ='Historical Data'!C11/'Historical Data'!C4 -> 0.27391304 | D10: ='Historical Data'!D11/'Historical Data'!D4 -> 0.28235294 | E10: ='Historical Data'!E11/'Historical Data'!E4 -> 0.29298246 | F10: ='Historical Data'!F11/'Historical Data'!F4 -> 0.296875
A11: Net Income | B11: ='Historical Data'!B14/'Historical Data'!B4 -> 0.19464286 | C11: ='Historical Data'!C14/'Historical Data'!C4 -> 0.20054348 | D11: ='Historical Data'!D14/'Historical Data'!D4 -> 0.20705882 | E11: ='Historical Data'!E14/'Historical Data'!E4 -> 0.21513158 | F11: ='Historical Data'!F14/'Historical Data'!F4 -> 0.21820312
A14: Comparative Analysis – Year-over-Year Growth
A15: Particulars | B15: 2020 | C15: 2021 | D15: 2022 | E15: 2023 | F15: 2024
A16: Revenue Growth | B16: N/A | C16: ='Historical Data'!C4/'Historical Data'!B4-1 -> 0.095238095 | D16: ='Historical Data'!D4/'Historical Data'!C4-1 -> 0.10869565 | E16: ='Historical Data'!E4/'Historical Data'!D4-1 -> 0.11764706 | F16: ='Historical Data'!F4/'Historical Data'!E4-1 -> 0.12280702
A17: Operating Exp Growth | B17: N/A | C17: ='Historical Data'!C5/'Historical Data'!B5-1 -> 0.086206897 | D17: ='Historical Data'!D5/'Historical Data'!C5-1 -> 0.095238095 | E17: ='Historical Data'!E5/'Historical Data'!D5-1 -> 0.10144928 | F17: ='Historical Data'!F5/'Historical Data'!E5-1 -> 0.11842105
A18: EBITA Growth | B18: N/A | C18: ='Historical Data'!C10/'Historical Data'!B10-1 -> 0.11538462 | D18: ='Historical Data'!D10/'Historical Data'!C10-1 -> 0.13793103 | E18: ='Historical Data'!E10/'Historical Data'!D10-1 -> 0.15151515 | F18: ='Historical Data'!F10/'Historical Data'!E10-1 -> 0.13157895
A19: Net Income Growth | B19: N/A | C19: ='Historical Data'!C14/'Historical Data'!B14-1 -> 0.12844037 | D19: ='Historical Data'!D14/'Historical Data'!C14-1 -> 0.14471545 | E19: ='Historical Data'!E14/'Historical Data'!D14-1 -> 0.16122159 | F19: ='Historical Data'!F14/'Historical Data'!E14-1 -> 0.13883792
A22: RATIO ANALYSIS
A23: Ratio | B23: 2020 | C23: 2021 | D23: 2022 | E23: 2023 | F23: 2024
A24: Current Ratio | B24: N/A | C24: N/A | D24: N/A | E24: N/A | F24: N/A
A25: Quick Ratio | B25: N/A | C25: N/A | D25: N/A | E25: N/A | F25: N/A
A26: Operating Margin | B26: ='Historical Data'!B10/'Historical Data'!B4 -> 0.30952381 | C26: ='Historical Data'!C10/'Historical Data'!C4 -> 0.31521739 | D26: ='Historical Data'!D10/'Historical Data'!D4 -> 0.32352941 | E26: ='Historical Data'!E10/'Historical Data'!E4 -> 0.33333333 | F26: ='Historical Data'!F10/'Historical Data'!F4 -> 0.3359375
A27: Net Profit Margin | B27: ='Historical Data'!B14/'Historical Data'!B4 -> 0.19464286 | C27: ='Historical Data'!C14/'Historical Data'!C4 -> 0.20054348 | D27: ='Historical Data'!D14/'Historical Data'!D4 -> 0.20705882 | E27: ='Historical Data'!E14/'Historical Data'!E4 -> 0.21513158 | F27: ='Historical Data'!F14/'Historical Data'!F4 -> 0.21820312
A28: ROE | B28: ='Historical Data'!B14/'Historical Data'!B21 -> 0.18579545 | C28: ='Historical Data'!C14/'Historical Data'!C21 -> 0.19020619 | D28: ='Historical Data'!D14/'Historical Data'!D21 -> 0.19738318 | E28: ='Historical Data'!E14/'Historical Data'!E21 -> 0.20609244 | F28: ='Historical Data'!F14/'Historical Data'!F21 -> 0.21
A29: Debt To Equity | B29: ='Historical Data'!B19/'Historical Data'!B21 -> 0.18181818 | C29: ='Historical Data'!C19/'Historical Data'!C21 -> 0.17525773 | D29: ='Historical Data'!D19/'Historical Data'!D21 -> 0.1682243 | E29: ='Historical Data'!E19/'Historical Data'!E21 -> 0.15966387 | F29: ='Historical Data'!F19/'Historical Data'!F21 -> 0.15037594
A30: Interest Coverage | B30: ='Historical Data'!B11/'Historical Data'!B7 -> 37.333333 | C30: ='Historical Data'!C11/'Historical Data'!C7 -> 42 | D30: ='Historical Data'!D11/'Historical Data'!D7 -> 45 | E30: ='Historical Data'!E11/'Historical Data'!E7 -> 47.714286 | F30: ='Historical Data'!F11/'Historical Data'!F7 -> 50
A33: TREND ANALYSIS
A34: Particulars | B34: 2020 | C34: 2021 | D34: 2022 | E34: 2023 | F34: 2024
A35: Revenue Trend | B35: ='Historical Data'!B4/'Historical Data'!B4*100 -> 100 | C35: ='Historical Data'!C4/'Historical Data'!$B$4*100 -> 109.52381 | D35: ='Historical Data'!D4/'Historical Data'!C4*100 -> 110.86957 | E35: ='Historical Data'!E4/'Historical Data'!D4*100 -> 111.76471 | F35: ='Historical Data'!F4/'Historical Data'!E4*100 -> 112.2807
A36: Net Income Trend | B36: ='Historical Data'!B14/'Historical Data'!B14*100 -> 100 | C36: ='Historical Data'!C14/'Historical Data'!$B$14*100 -> 112.84404 | D36: ='Historical Data'!D14/'Historical Data'!$B$14*100 -> 129.17431 | E36: ='Historical Data'!E14/'Historical Data'!$B$14*100 -> 150 | F36: ='Historical Data'!F14/'Historical Data'!$B$14*100 -> 170.82569

Sheet Statement Model
A1: Greenfield Pharma Ltd – 3 Statement Model
A3: Particulars | B3: 2020 | C3: 2021 | D3: 2022 | E3: 2023 | F3: 2024
A5: Income Statement
A6: Revenue | B6: ='Historical Data'!B4 -> 42000 | C6: ='Historical Data'!C4 -> 46000 | D6: ='Historical Data'!D4 -> 51000 | E6: ='Historical Data'!E4 -> 57000 | F6: ='Historical Data'!F4 -> 64000
A7: EBITA | B7: ='Historical Data'!B10 -> 13000 | C7: ='Historical Data'!C10 -> 14500 | D7: ='Historical Data'!D10 -> 16500 | E7: ='Historical Data'!E10 -> 19000 | F7: ='Historical Data'!F10 -> 21500
A8: Depriciation | B8: ='Historical Data'!B6 -> 1800 | C8: ='Historical Data'!C6 -> 1900 | D8: ='Historical Data'!D6 -> 2100 | E8: ='Historical Data'!E6 -> 2300 | F8: ='Historical Data'!F6 -> 2500
A9: EBITA | B9: ='Historical Data'!B11 -> 11200 | C9: ='Historical Data'!C11 -> 12600 | D9: ='Historical Data'!D11 -> 14400 | E9: ='Historical Data'!E11 -> 16700 | F9: ='Historical Data'!F11 -> 19000
A10: Intrest | B10: ='Historical Data'!B7 -> 300 | C10: ='Historical Data'!C7 -> 300 | D10: ='Historical Data'!D7 -> 320 | E10: ='Historical Data'!E7 -> 350 | F10: ='Historical Data'!F7 -> 380
A11: Profit Before Tax | B11: ='Historical Data'!B12 -> 10900 | C11: ='Historical Data'!C12 -> 12300 | D11: ='Historical Data'!D12 -> 14080 | E11: ='Historical Data'!E12 -> 16350 | F11: ='Historical Data'!F12 -> 18620
A12: Tax | B12: ='Historical Data'!B13 -> 2725 | C12: ='Historical Data'!C13 -> 3075 | D12: ='Historical Data'!D13 -> 3520 | E12: ='Historical Data'!E13 -> 4087.5 | F12: ='Historical Data'!F13 -> 4655
A13: Net Income | B13: ='Historical Data'!B14 -> 8175 | C13: ='Historical Data'!C14 -> 9225 | D13: ='Historical Data'!D14 -> 10560 | E13: ='Historical Data'!E14 -> 12262.5 | F13: ='Historical Data'!F14 -> 13965
A15: BALANCE SHEET
A16: Particulars | B16: 2020 | C16: 2021 | D16: 2022 | E16: 2023 | F16: 2024
A17: Total Assets | B17: ='Historical Data'!B18 -> 55000 | C17: ='Historical Data'!C18 -> 60000 | D17: ='Historical Data'!D18 -> 66000 | E17: ='Historical Data'!E18 -> 73000 | F17: ='Historical Data'!F18 -> 81000
A18: Total Debt | B18: ='Historical Data'!B19 -> 8000 | C18: ='Historical Data'!C19 -> 8500 | D18: ='Historical Data'!D19 -> 9000 | E18: ='Historical Data'!E19 -> 9500 | F18: ='Historical Data'!F19 -> 10000
A19: Cash | B19: ='Historical Data'!B20 -> 6000 | C19: ='Historical Data'!C20 -> 7200 | D19: ='Historical Data'!D20 -> 8500 | E19: ='Historical Data'!E20 -> 10000 | F19: ='Historical Data'!F20 -> 11800
A20: Equity | B20: ='Historical Data'!B21 -> 44000 | C20: ='Historical Data'!C21 -> 48500 | D20: ='Historical Data'!D21 -> 53500 | E20: ='Historical Data'!E21 -> 59500 | F20: ='Historical Data'!F21 -> 66500
A22: Retained Earnings Schedule
A23: Particulars | B23: 2020 | C23: 2021 | D23: 2022 | E23: 2023 | F23: 2024
A24: Opening Retained Earnings | B24: N/A | C24: =0 -> 0 | D24: =C27 -> 9225 | E24: =D27 -> 19785 | F24: =E27 -> 32047.5 | I24: RE= Beginning RE + Net Income - Dividends
A25: Net Income | B25: =B13 -> 8175 | C25: =C13 -> 9225 | D25: =D13 -> 10560 | E25: =E13 -> 12262.5 | F25: =F13 -> 13965
A26: Dividends | B26: 0 | C26: 0 | D26: 0 | E26: 0 | F26: 0
A27: Closed Retained Earnings | B27: N/A | C27: =C24+C25-C26 -> 9225 | D27: =D24+D25-D26 -> 19785 | E27: =E24+E25-E26 -> 32047.5 | F27: =F24+F25-F26 -> 46012.5 | I27: Because we don’t have dividend data , we cannot calculate a proper Retained Earning .
A29: Cash Flow Statements
A30: Particulars | B30: 2020 | C30: 2021 | D30: 2022 | E30: 2023 | F30: 2024
A31: Net income | B31: =B13 -> 8175 | C31: =C13 -> 9225 | D31: =D13 -> 10560 | E31: =E13 -> 12262.5 | F31: =F13 -> 13965
A32: Depriciation | B32: =B8 -> 1800 | C32: =C8 -> 1900 | D32: =D8 -> 2100 | E32: =E8 -> 2300 | F32: =F8 -> 2500
A33: Cash Flow From Operations | B33: =B31+B32 -> 9975 | C33: =C31+C32 -> 11125 | D33: =D31+D32 -> 12660 | E33: =E31+E32 -> 14562.5 | F33: =F31+F32 -> 16465
A34: Capital Expenditure | B34: N/A | C34: N/A | D34: N/A | E34: N/A | F34: N/A
A35: Cash Flow From Investing | B35: N/A | C35: N/A | D35: N/A | E35: N/A | F35: N/A | I35: Investing Activity Not calculated as no capital expenditure was made
A36: Change In Debt | B36: N/A | C36: ='Historical Data'!C19-'Historical Data'!B19 -> 500 | D36: ='Historical Data'!D19-'Historical Data'!C19 -> 500 | E36: ='Historical Data'!E19-'Historical Data'!D19 -> 500 | F36: ='Historical Data'!F19-'Historical Data'!E19 -> 500
A37: Cash Flow From Financing | B37: N/A | C37: N/A | D37: N/A | E37: N/A | F37: N/A
A38: Net Change In Cash | B38: N/A | C38: N/A | D38: N/A | E38: N/A | F38: N/A
A39: Beginning Cash | B39: ='Historical Data'!B20 -> 6000 | C39: ='Historical Data'!C20 -> 7200 | D39: ='Historical Data'!D20 -> 8500 | E39: ='Historical Data'!E20 -> 10000 | F39: ='Historical Data'!F20 -> 11800
A40: Ending Cash | B40: ='Historical Data'!B20 -> 6000 | C40: ='Historical Data'!C20 -> 7200 | D40: ='Historical Data'!D20 -> 8500 | E40: ='Historical Data'!E20 -> 10000 | F40: ='Historical Data'!F20 -> 11800

Sheet Forecast
A1: Greenfield Pharma Ltd – Financial Forecast
A3: Particulars | B3: 2024 | C3: 2025 | D3: 2026 | E3: 2027 | F3: 2028 | G3: 2029 | J3: Expected Growth Rate : 7%
J4: Future Revenue = Previous Year Revenue × (1 + Growth Rate)
A5: Revenue Growth Rate | B5: N/A | C5: ='Historical Data'!B29 -> 0.07 | D5: ='Historical Data'!B29 -> 0.07 | E5: ='Historical Data'!B29 -> 0.07 | F5: ='Historical Data'!B29 -> 0.07
A6: Revenue | B6: ='Historical Data'!F4 -> 64000 | C6: =B6*(1+C5) -> 68480 | D6: =C6*(1+D5) -> 73273.6 | E6: =D6*(1+E5) -> 78402.752 | F6: =E6*(1+F5) -> 83890.945 | G6: 89763.31
A8: Operating expenses Margin | B8: ='Historical Data'!F5/'Historical Data'!F4 -> 0.6640625 | C8: ='Historical Data'!F5/'Historical Data'!F4 -> 0.6640625 | D8: ='Historical Data'!F5/'Historical Data'!F4 -> 0.6640625 | E8: ='Historical Data'!F5/'Historical Data'!F4 -> 0.6640625 | F8: ='Historical Data'!F5/'Historical Data'!F4 -> 0.6640625 | J8: Operating Expenses Margin = Operating expenses/ Revenue
A9: Operating Expenses | B9: =B6*B8 -> 42500 | C9: =C6*C8 -> 45475 | D9: =D6*D8 -> 48658.25 | E9: =E6*E8 -> 52064.328 | F9: =F6*F8 -> 55708.83 | G9: 59605.16 | J9: Operating Expenses = Forcast Revenue*Operating expenses Margin
A11: EBITA | B11: =B6-B9 -> 21500 | C11: =C6-C9 -> 23005 | D11: =D6-D9 -> 24615.35 | E11: =E6-E9 -> 26338.425 | F11: =F6-F9 -> 28182.114 | G11: =G6-G9 -> 30158.15 | J11: EBITA = Revenue − Operating Expenses
A12: EBITA Margin | B12: =B11/B6 -> 0.3359375 | C12: =C11/C6 -> 0.3359375 | D12: =D11/D6 -> 0.3359375 | E12: =E11/E6 -> 0.3359375 | F12: =F11/F6 -> 0.3359375 | G12: 0.3359 | J12: EBITA Margin= EBITA/ Forecast Revenue
A14: Depriciation | B14: =B6*(2500/64000) -> 2500 | C14: =C6*(2500/64000) -> 2675 | D14: =D6*(2500/64000) -> 2862.25 | E14: =E6*(2500/64000) -> 3062.6075 | F14: =F6*(2500/64000) -> 3276.99 | G14: 3506.44
A15: Operating Profit | B15: =B11-B14 -> 19000 | C15: =C11-C14 -> 20330 | D15: =D11-D14 -> 21753.1 | E15: =E11-E14 -> 23275.817 | F15: =F11-F14 -> 24905.124 | G15: 26653.19
A16: Intrest | B16: ='Historical Data'!F7 -> 380 | C16: 380 | D16: 380 | E16: 380 | F16: 380 | G16: 380
A17: Profit Before Tax | B17: =B15-B16 -> 18620 | C17: =C15-C16 -> 19950 | D17: =D15-D16 -> 21373.1 | E17: =E15-E16 -> 22895.817 | F17: =F15-F16 -> 24525.124 | G17: 26273.19
A18: Tax | B18: =B17*'Historical Data'!$F$8 -> 4655 | C18: =C17*'Historical Data'!$F$8 -> 4987.5 | D18: =D17*'Historical Data'!$F$8 -> 5343.275 | E18: =E17*'Historical Data'!$F$8 -> 5723.9543 | F18: =F17*'Historical Data'!$F$8 -> 6131.281 | G18: 6568.3
A19: Net Profit | B19: =B17-B18 -> 13965 | C19: =C17-C18 -> 14962.5 | D19: =D17-D18 -> 16029.825 | E19: =E17-E18 -> 17171.863 | F19: =F17-F18 -> 18393.843 | G19: 19704.89
A20: Cash Flow | B20: =B19+B14 -> 16465 | C20: =C19+C14 -> 17637.5 | D20: =D19+D14 -> 18892.075 | E20: =E19+E14 -> 20234.47 | F20: =F19+F14 -> 21670.833 | G20: 23211.33
A22: NOPAT | B22: =B15*(1-'Historical Data'!$F$8) -> 14250 | C22: =C15*(1-'Historical Data'!$F$8) -> 15247.5 | D22: =D15*(1-'Historical Data'!$F$8) -> 16314.825 | E22: =E15*(1-'Historical Data'!$F$8) -> 17456.863 | F22: =F15*(1-'Historical Data'!$F$8) -> 18678.843 | G22: 19989.89 | J22: NOPAT = EBIT* (1- Tax rate )
A23: UFCF | B23: =B22+B14 -> 16750 | C23: =C22+C14 -> 17922.5 | D23: =D22+D14 -> 19177.075 | E23: =E22+E14 -> 20519.47 | F23: =F22+F14 -> 21955.833 | G23: 23496.33 | J23: Unleavered Free cash Flow (UFCF) = NOPAT + Depriciation
A25: Cost of Equity | B25: ='Historical Data'!B24+'Historical Data'!B26*('Historical Data'!B25-'Historical Data'!B24) -> 0.111 | C25: ='Historical Data'!B24+'Historical Data'!B26*('Historical Data'!B25-'Historical Data'!B24) -> 0.111 | D25: ='Historical Data'!B24+'Historical Data'!B26*('Historical Data'!B25-'Historical Data'!B24) -> 0.111 | E25: ='Historical Data'!B24+'Historical Data'!B26*('Historical Data'!B25-'Historical Data'!B24) -> 0.111 | F25: ='Historical Data'!B24+'Historical Data'!B26*('Historical Data'!B25-'Historical Data'!B24) -> 0.111 | G25: ='Historical Data'!B24+'Historical Data'!B26*('Historical Data'!B25-'Historical Data'!B24) -> 0.111 | J25: Cost Of Equity Using CAPM = Risk Free rate + company Beta*(Expected market Return*risk free rate)
A26: WACC | B26: =B25*(66500/(66500+10000))+7%*(1-25%)*(10000/(66500+10000)) -> 0.10335294 | C26: =C25*(66500/(66500+10000))+7%*(1-25%)*(10000/(66500+10000)) -> 0.10335294 | D26: =D25*(66500/(66500+10000))+7%*(1-25%)*(10000/(66500+10000)) -> 0.10335294 | E26: =E25*(66500/(66500+10000))+7%*(1-25%)*(10000/(66500+10000)) -> 0.10335294 | F26: =F25*(66500/(66500+10000))+7%*(1-25%)*(10000/(66500+10000)) -> 0.10335294 | G26: =F25*(66500/(66500+10000))+7%*(1-25%)*(10000/(66500+10000)) -> 0.10335294 | J26: WACC= Equity/Debt + Equity * Cost of equity + Debt/Equity + Debt * Cost of debt *(1- Tax)
A27: Terminal Value | G27: =G23*(1+'Historical Data'!B29)/($B$26-'Historical Data'!B29) -> 753788.79
A28: Enterprise Value | J28: Equity | K28: ='Historical Data'!F21 -> 66500 | M28: Total capital = | N28: =K28+K29 -> 76500
A29: Year | B29: 2025 | C29: 2026 | D29: 2027 | E29: 2028 | F29: 2029 | J29: Debt | K29: ='Historical Data'!F19 -> 10000 | M29: Equity weight | N29: =K28/N28 -> 0.86928105
A30: UFCF | B30: =C23 -> 17922.5 | C30: =D23 -> 19177.075 | D30: =E23 -> 20519.47 | E30: =F23 -> 21955.833 | F30: =G23 -> 23496.33 | J30: Cost of equity | K30: =F25 -> 0.111 | M30: Debt weight | N30: =K29/N28 -> 0.13071895
A31: Discount Factor | B31: =1/(1+$B$26)^1 -> 0.9063283 | C31: =1/(1+$B$26)^2 -> 0.82143099 | D31: =1/(1+$B$26)^3 -> 0.74448616 | E31: =1/(1+$B$26)^4 -> 0.67474888 | F31: =1/(1+$B$26)^5 -> 0.61154401 | J31: Cost Of Debt | K31: ='Historical Data'!B27 -> 0.07
A32: PV of UFCF | B32: =B30*B31 -> 16243.669 | C32: =C30*C31 -> 15752.644 | D32: =D30*D31 -> 15276.462 | E32: =E30*E31 -> 14814.674 | F32: =F30*F31 -> 14369.04 | J32: Tax Rate | K32: ='Historical Data'!F8 -> 0.25
A33: Enterprise Value | B33: =SUM(B32:F32)+G27*F31 -> 537431.5
A34: Equity Value | B34: =B33-10000+11800 -> 539231.5
A35: Value Per Share | B35: =B34/160 -> 3370.1969
A37: BOOK VALUE VALUATION
A38: Book Value Per Share | B38: =66500/160 -> 415.625 | J38: Book value per share = Equity ÷ Shares Outstanding
A39: Adjusted Book Value Method | B39: The Adjusted Book Value Method calculates a company’s value by
B40: updating its balance sheet items to current fair market values. Subtracting adjusted liabilities from
B41: adjusted assets gives you the company's real net asset value—making this approach ideal when historical book values are out of date.
A43: Enterprise Value and EBITDA
A44: EBITDA | B44: ='Historical Data'!F10 -> 21500
A45: Enterprise Value | B45: =K28+K29-'Historical Data'!F20 -> 64700 | J45: Enterprise Value = Equity + Debt - Cash
A47: RELATIVE VALUATION
A48: Comparable Company | B48: EV/EBITDA | C48: P/E
A49: Sun Pharma | B49: 22 | C49: 34
...

Sheet Charts
A1: Financial Analysis Charts
A3: Revenue Growth
A4: Year | B4: Revenue Growth
A5: 2021 | B5: ='Historical Data'!C34 -> 0.095238095
A6: 2022 | B6: ='Historical Data'!D34 -> 0.10869565
A7: 2023 | B7: ='Historical Data'!E34 -> 0.11764706
A8: 2024 | B8: ='Historical Data'!F34 -> 0.12280702
A10: Profit Growth
A11: Year | B11: Net Income Growth
A12: 2021 | B12: ='Historical Data'!C35 -> 0.12844037
A13: 2022 | B13: ='Historical Data'!D35 -> 0.14471545
A14: 2023 | B14: ='Historical Data'!E35 -> 0.16122159
A15: 2024 | B15: ='Historical Data'!F35 -> 0.13883792
A17: Ratio Comparision
A18: Ratio | B18: 2024 | C18: Chart Value
A19: Operating Margin | B19: ='Financial Analysis'!F26 -> 0.3359375 | C19: =33.59 -> 33.59
A20: Net Profit Margin | B20: ='Financial Analysis'!F27 -> 0.21820312 | C20: 21.82
A21: ROE | B21: ='Financial Analysis'!F28 -> 0.21 | C21: 21
A22: Debt/Equity | B22: ='Financial Analysis'!F29 -> 0.15037594 | C22: 0.15
A23: Intrest Coverage | B23: ='Financial Analysis'!F30 -> 50 | C23: 50
