Workbook

Sheet Historical  Data
A1: Nexora Technologies Ltd — Historical Financial Data
A3: Particulars | B3: 2020 | C3: 2021 | D3: 2022 | E3: 2023 | F3: 2024
A4: Revenue | B4: 78000 | C4: 84000 | D4: 92000 | E4: 101000 | F4: 112000
A5: Operating Expenses | B5: 56000 | C5: 60000 | D5: 65000 | E5: 71000 | F5: 78000
A6: Depriciation | B6: 3200 | C6: 3400 | D6: 3700 | E6: 4000 | F6: 4300
A7: Intrest | B7: 400 | C7: 400 | D7: 450 | E7: 500 | F7: 550
A8: Tax Rates | B8: 0.25 | C8: 0.25 | D8: 0.25 | E8: 0.25 | F8: 0.25
A9: BALANCE SHEET
A10: Total Assets | B10: 105000 | C10: 114000 | D10: 124000 | E10: 137000 | F10: 150000
A11: Debt | B11: 15000 | C11: 16500 | D11: 17500 | E11: 19000 | F11: 20500
A12: Cash | B12: 9000 | C12: 11000 | D12: 13500 | E12: 16000 | F12: 18500
A13: Equity | B13: 90000 | C13: 97500 | D13: 106500 | E13: 118000 | F13: 129500
A15: EBITDA | B15: =B4-B5 -> 22000 | C15: =C4-C5 -> 24000 | D15: =D4-D5 -> 27000 | E15: =E4-E5 -> 30000 | F15: =F4-F5 -> 34000
A16: EBIT | B16: =B15-B6 -> 18800 | C16: =C15-C6 -> 20600 | D16: =D15-D6 -> 23300 | E16: =E15-E6 -> 26000 | F16: =F15-F6 -> 29700
A17: PBT | B17: =B16-B7 -> 18400 | C17: =C16-C7 -> 20200 | D17: =D16-D7 -> 22850 | E17: =E16-E7 -> 25500 | F17: =F16-F7 -> 29150
A18: Tax | B18: =B17*B8 -> 4600 | C18: =C17*C8 -> 5050 | D18: =D17*D8 -> 5712.5 | E18: =E17*E8 -> 6375 | F18: =F17*F8 -> 7287.5
A19: Net Profit | B19: =B17-B18 -> 13800 | C19: =C17-C18 -> 15150 | D19: =D17-D18 -> 17137.5 | E19: =E17-E18 -> 19125 | F19: =F17-F18 -> 21862.5
A22: Risk Free Rate | B22: 0.055
A23: Market Return | B23: 0.115
A24: Equity Beta | B24: 1.05
A25: Cost Of Debt | B25: 0.075
A26: Share Outstanding | B26: 380
A27: Expected Growth | B27: 0.06

Sheet Financial Analysis
A1: Nexora Technologies Ltd — Financial Analysis
A2: Particulars | B2: 2020 | C2: 2021 | D2: 2022 | E2: 2023 | F2: 2024
A4: Revenue | B4: ='Historical Data'!B4 -> 78000 | C4: ='Historical Data'!C4 -> 84000 | D4: ='Historical Data'!D4 -> 92000 | E4: ='Historical Data'!E4 -> 101000 | F4: ='Historical Data'!F4 -> 112000
A5: Operating Expenses | B5: ='Historical Data'!B5 -> 56000 | C5: ='Historical Data'!C5 -> 60000 | D5: ='Historical Data'!D5 -> 65000 | E5: ='Historical Data'!E5 -> 71000 | F5: ='Historical Data'!F5 -> 78000
A6: Depriciation | B6: ='Historical Data'!B6 -> 3200 | C6: ='Historical Data'!C6 -> 3400 | D6: ='Historical Data'!D6 -> 3700 | E6: ='Historical Data'!E6 -> 4000 | F6: ='Historical Data'!F6 -> 4300
A7: Intrest | B7: ='Historical Data'!B7 -> 400 | C7: ='Historical Data'!C7 -> 400 | D7: ='Historical Data'!D7 -> 450 | E7: ='Historical Data'!E7 -> 500 | F7: ='Historical Data'!F7 -> 550
A8: EBITDA | B8: ='Historical Data'!B15 -> 22000 | C8: ='Historical Data'!C15 -> 24000 | D8: ='Historical Data'!D15 -> 27000 | E8: ='Historical Data'!E15 -> 30000 | F8: ='Historical Data'!F15 -> 34000
A9: EBIT | B9: ='Historical Data'!B16 -> 18800 | C9: ='Historical Data'!C16 -> 20600 | D9: ='Historical Data'!D16 -> 23300 | E9: ='Historical Data'!E16 -> 26000 | F9: ='Historical Data'!F16 -> 29700
A10: Net Profit | B10: ='Historical Data'!B19 -> 13800 | C10: ='Historical Data'!C19 -> 15150 | D10: ='Historical Data'!D19 -> 17137.5 | E10: ='Historical Data'!E19 -> 19125 | F10: ='Historical Data'!F19 -> 21862.5
A14: Common-Size Analysis (% of Revenue)
A15: Revenue | B15: 1 | C15: 1 | D15: 1 | E15: 1 | F15: 1
A16: Operating Expenses | B16: =B5/$B$4 -> 0.71794872 | C16: =C5/C4 -> 0.71428571 | D16: =D5/D4 -> 0.70652174 | E16: =E5/E4 -> 0.7029703 | F16: =F5/F4 -> 0.69642857
A17: Depriciation | B17: =B6/B4 -> 0.041025641 | C17: =C6/C4 -> 0.04047619 | D17: =D6/D4 -> 0.040217391 | E17: =E6/E4 -> 0.03960396 | F17: =F6/F4 -> 0.038392857
A18: Intrest | B18: =B7/B4 -> 0.0051282051 | C18: =C7/C4 -> 0.0047619048 | D18: =D7/D4 -> 0.0048913043 | E18: =E7/E4 -> 0.004950495 | F18: =F7/F4 -> 0.0049107143
A19: EBITDA | B19: =B8/B4 -> 0.28205128 | C19: =C8/C4 -> 0.28571429 | D19: =D8/D4 -> 0.29347826 | E19: =E8/E4 -> 0.2970297 | F19: =F8/F4 -> 0.30357143
A20: EBIT | B20: =B9/B4 -> 0.24102564 | C20: =C9/C4 -> 0.2452381 | D20: =D9/D4 -> 0.25326087 | E20: =E9/E4 -> 0.25742574 | F20: =F9/F4 -> 0.26517857
A21: Net Profit | B21: =B10/B4 -> 0.17692308 | C21: =C10/C4 -> 0.18035714 | D21: =D10/D4 -> 0.18627717 | E21: =E10/E4 -> 0.18935644 | F21: =F10/F4 -> 0.19520089
A22: Comparative / Growth Analysis
A23: Revenue Growth | B23: N/A | C23: =C4/B4-1 -> 0.076923077 | D23: =D4/C4-1 -> 0.095238095 | E23: =E4/D4-1 -> 0.097826087 | F23: =F4/E4-1 -> 0.10891089
A24: Operating Expenses Growth | B24: N/A | C24: =C5/B5-1 -> 0.071428571 | D24: =D5/C5-1 -> 0.083333333 | E24: =E5/D5-1 -> 0.092307692 | F24: =F5/E5-1 -> 0.098591549
A25: EBITDA Growth | B25: N/A | C25: =C8/B8-1 -> 0.090909091 | D25: =D8/C8-1 -> 0.125 | E25: =E8/D8-1 -> 0.11111111 | F25: =F8/E8-1 -> 0.13333333
A26: Net Profit Growth | B26: N/A | C26: =C10/B10-1 -> 0.097826087 | D26: =D10/C10-1 -> 0.13118812 | E26: =E10/D10-1 -> 0.11597374 | F26: =F10/E10-1 -> 0.14313725
A28: Key Financial Ratios
A29: Operating Margin Ratio | B29: =B8/B4 -> 0.28205128 | C29: =C8/C4 -> 0.28571429 | D29: =D8/D4 -> 0.29347826 | E29: =E8/E4 -> 0.2970297 | F29: =F8/F4 -> 0.30357143
A30: Net Profit Margin Ratio | B30: =B10/B4 -> 0.17692308 | C30: =C10/C4 -> 0.18035714 | D30: =D10/D4 -> 0.18627717 | E30: =E10/E4 -> 0.18935644 | F30: =F10/F4 -> 0.19520089
A31: Return On Equity Ratio (ROE) | B31: ='Historical Data'!B19/'Historical Data'!B13 -> 0.15333333 | C31: ='Historical Data'!C19/'Historical Data'!C13 -> 0.15538462 | D31: ='Historical Data'!D19/'Historical Data'!D13 -> 0.16091549 | E31: ='Historical Data'!E19/'Historical Data'!E13 -> 0.16207627 | F31: ='Historical Data'!F19/'Historical Data'!F13 -> 0.16882239
A32: Debt To Equity Ratio | B32: ='Historical Data'!B11/'Historical Data'!B13 -> 0.16666667 | C32: ='Historical Data'!C11/'Historical Data'!C13 -> 0.16923077 | D32: ='Historical Data'!D11/'Historical Data'!D13 -> 0.16431925 | E32: ='Historical Data'!E11/'Historical Data'!E13 -> 0.16101695 | F32: ='Historical Data'!F11/'Historical Data'!F13 -> 0.15830116
A33: Intrest Coverage | B33: =B9/B7 -> 47 | C33: =C9/C7 -> 51.5 | D33: =D9/D7 -> 51.777778 | E33: =E9/E7 -> 52 | F33: =F9/F7 -> 54
A35: Additional Ratios
A36: Asset Turnover ratio | B36: =B4/'Historical Data'!B10 -> 0.74285714 | C36: =C4/'Historical Data'!C10 -> 0.73684211 | D36: =D4/'Historical Data'!D10 -> 0.74193548 | E36: =E4/'Historical Data'!E10 -> 0.73722628 | F36: =F4/'Historical Data'!F10 -> 0.74666667
A37: Debt Ratio | B37: ='Historical Data'!B11/'Historical Data'!B10 -> 0.14285714 | C37: ='Historical Data'!C11/'Historical Data'!C10 -> 0.14473684 | D37: ='Historical Data'!D11/'Historical Data'!D10 -> 0.14112903 | E37: ='Historical Data'!E11/'Historical Data'!E10 -> 0.13868613 | F37: ='Historical Data'!F11/'Historical Data'!F10 -> 0.13666667
A38: Current ratio | B38: N/A | C38: N/A | D38: N/A | E38: N/A | F38: N/A
A39: Quick Ratio | B39: N/A | C39: N/A | D39: N/A | E39: N/A | F39: N/A
A41: Trend Analysis (2020 = 100)
A42: Revenue Trend | B42: =B4/$B$4*100 -> 100 | C42: =C4/$B$4*100 -> 107.69231 | D42: =D4/$B$4*100 -> 117.94872 | E42: =E4/$B$4*100 -> 129.48718 | F42: =F4/$B$4*100 -> 143.58974
A43: EBITDA Trend | B43: =100 -> 100 | C43: =C8/$B$8*100 -> 109.09091 | D43: =D8/$B$8*100 -> 122.72727 | E43: =E8/$B$8*100 -> 136.36364 | F43: =F8/$B$8*100 -> 154.54545
A44: Profit Trend | B44: =B10/$B$10*100 -> 100 | C44: =C10/$B$10*100 -> 109.78261 | D44: =D10/$B$10*100 -> 124.18478 | E44: =E10/$B$10*100 -> 138.58696 | F44: =F10/$B$10*100 -> 158.42391

Sheet 3 Statement Model
A1: Nexora Technologies Ltd — 3-Statement Model
A3: Particulars | B3: 2020 | C3: 2021 | D3: 2022 | E3: 2023 | F3: 2024
A5: Income Statement
A6: Revenue | B6: ='Historical Data'!B4 -> 78000 | C6: ='Historical Data'!C4 -> 84000 | D6: ='Historical Data'!D4 -> 92000 | E6: ='Historical Data'!E4 -> 101000 | F6: ='Historical Data'!F4 -> 112000
A7: Operating Expenses | B7: ='Historical Data'!B5 -> 56000 | C7: ='Historical Data'!C5 -> 60000 | D7: ='Historical Data'!D5 -> 65000 | E7: ='Historical Data'!E5 -> 71000 | F7: ='Historical Data'!F5 -> 78000
A8: EBITDA | B8: ='Historical Data'!B15 -> 22000 | C8: ='Historical Data'!C15 -> 24000 | D8: ='Historical Data'!D15 -> 27000 | E8: ='Historical Data'!E15 -> 30000 | F8: ='Historical Data'!F15 -> 34000
A9: Depriciation | B9: ='Historical Data'!B6 -> 3200 | C9: ='Historical Data'!C6 -> 3400 | D9: ='Historical Data'!D6 -> 3700 | E9: ='Historical Data'!E6 -> 4000 | F9: ='Historical Data'!F6 -> 4300
A10: EBIT | B10: ='Historical Data'!B16 -> 18800 | C10: ='Historical Data'!C16 -> 20600 | D10: ='Historical Data'!D16 -> 23300 | E10: ='Historical Data'!E16 -> 26000 | F10: ='Historical Data'!F16 -> 29700
A11: Intrest | B11: ='Historical Data'!B7 -> 400 | C11: ='Historical Data'!C7 -> 400 | D11: ='Historical Data'!D7 -> 450 | E11: ='Historical Data'!E7 -> 500 | F11: ='Historical Data'!F7 -> 550
A12: PBT | B12: ='Historical Data'!B17 -> 18400 | C12: ='Historical Data'!C17 -> 20200 | D12: ='Historical Data'!D17 -> 22850 | E12: ='Historical Data'!E17 -> 25500 | F12: ='Historical Data'!F17 -> 29150
A13: Tax | B13: ='Historical Data'!B18 -> 4600 | C13: ='Historical Data'!C18 -> 5050 | D13: ='Historical Data'!D18 -> 5712.5 | E13: ='Historical Data'!E18 -> 6375 | F13: ='Historical Data'!F18 -> 7287.5
A14: Net Income | B14: ='Historical Data'!B19 -> 13800 | C14: ='Historical Data'!C19 -> 15150 | D14: ='Historical Data'!D19 -> 17137.5 | E14: ='Historical Data'!E19 -> 19125 | F14: ='Historical Data'!F19 -> 21862.5
A16: Retained Earnings
A17: Opening Retained Earnings | B17: N/A
A18: Net Income | B18: =B14 -> 13800 | C18: =C14 -> 15150 | D18: =D14 -> 17137.5 | E18: =E14 -> 19125 | F18: =F14 -> 21862.5
A19: Dividend | B19: N/A
A20: Closing Retained Earnings | B20: N/A
A22: Balance Sheet
A23: Total Asset | B23: ='Historical Data'!B10 -> 105000 | C23: ='Historical Data'!C10 -> 114000 | D23: ='Historical Data'!D10 -> 124000 | E23: ='Historical Data'!E10 -> 137000 | F23: ='Historical Data'!F10 -> 150000
A24: Debt | B24: ='Historical Data'!B11 -> 15000 | C24: ='Historical Data'!C11 -> 16500 | D24: ='Historical Data'!D11 -> 17500 | E24: ='Historical Data'!E11 -> 19000 | F24: ='Historical Data'!F11 -> 20500
A25: Cash | B25: ='Historical Data'!B12 -> 9000 | C25: ='Historical Data'!C12 -> 11000 | D25: ='Historical Data'!D12 -> 13500 | E25: ='Historical Data'!E12 -> 16000 | F25: ='Historical Data'!F12 -> 18500
A26: Equity | B26: ='Historical Data'!B13 -> 90000 | C26: ='Historical Data'!C13 -> 97500 | D26: ='Historical Data'!D13 -> 106500 | E26: ='Historical Data'!E13 -> 118000 | F26: ='Historical Data'!F13 -> 129500
A28: Cash Flow Statement
A29: Net Income | B29: =B14 -> 13800 | C29: =C14 -> 15150 | D29: =D14 -> 17137.5 | E29: =E14 -> 19125 | F29: =F14 -> 21862.5
A30: Depriciation | B30: =B9 -> 3200 | C30: =C9 -> 3400 | D30: =D9 -> 3700 | E30: =E9 -> 4000 | F30: =F9 -> 4300
A31: Cash Flow From Operations | B31: =B29+B30 -> 17000 | C31: =C29+C30 -> 18550 | D31: =D29+D30 -> 20837.5 | E31: =E29+E30 -> 23125 | F31: =F29+F30 -> 26162.5

Sheet 5 Years Forecast
A1: Nexora Technologies Ltd — 5-Year Forecast
A3: Particulars | B3: 2020 | C3: 2021 | D3: 2022 | E3: 2023 | F3: 2024 | G3: 2025 | H3: 2026 | I3: 2027 | J3: 2028 | K3: 2029 | M3: Forecast Assumptions
M4: Revenue Growth | N4: 0.06
A5: Revenue | B5: ='Historical Data'!B4 -> 78000 | C5: ='Historical Data'!C4 -> 84000 | D5: ='Historical Data'!D4 -> 92000 | E5: ='Historical Data'!E4 -> 101000 | F5: ='Historical Data'!F4 -> 112000 | G5: =F5*(1+$N$4) -> 118720 | H5: =G5*(1+$N$4) -> 125843.2 | I5: =H5*(1+$N$4) -> 133393.79 | J5: =I5*(1+$N$4) -> 141397.42 | K5: =J5*(1+$N$4) -> 149881.26 | M5: Operating Expense % of Revenue | N5: =F6/F5 -> 0.69642857
A6: Operating Expenses | B6: ='Historical Data'!B5 -> 56000 | C6: ='Historical Data'!C5 -> 60000 | D6: ='Historical Data'!D5 -> 65000 | E6: ='Historical Data'!E5 -> 71000 | F6: ='Historical Data'!F5 -> 78000 | G6: =G5*$N$5 -> 82680 | H6: =H5*$N$5 -> 87640.8 | I6: =I5*$N$5 -> 92899.248 | J6: =J5*$N$5 -> 98473.203 | K6: =K5*$N$5 -> 104381.6 | M6: Depreciation % of Revenue | N6: =F8/F5 -> 0.038392857
A7: EBITDA | B7: ='Historical Data'!B15 -> 22000 | C7: ='Historical Data'!C15 -> 24000 | D7: ='Historical Data'!D15 -> 27000 | E7: ='Historical Data'!E15 -> 30000 | F7: ='Historical Data'!F15 -> 34000 | G7: =G5*$N$8 -> 36040 | H7: =H5*$N$8 -> 38202.4 | I7: =I5*$N$8 -> 40494.544 | J7: =J5*$N$8 -> 42924.217 | K7: =K5*$N$8 -> 45499.67 | M7: Tax Rate | N7: 0.25
A8: Depriciation | B8: ='Historical Data'!B6 -> 3200 | C8: ='Historical Data'!C6 -> 3400 | D8: ='Historical Data'!D6 -> 3700 | E8: ='Historical Data'!E6 -> 4000 | F8: ='Historical Data'!F6 -> 4300 | G8: =G5*$N$6 -> 4558 | H8: =H5*$N$6 -> 4831.48 | I8: =I5*$N$6 -> 5121.3688 | J8: =J5*$N$6 -> 5428.6509 | K8: =K5*$N$6 -> 5754.37 | M8: EBITDA Margin | N8: =F7/F5 -> 0.30357143
A9: EBIT | B9: ='Historical Data'!B16 -> 18800 | C9: ='Historical Data'!C16 -> 20600 | D9: ='Historical Data'!D16 -> 23300 | E9: ='Historical Data'!E16 -> 26000 | F9: ='Historical Data'!F16 -> 29700 | G9: =G7-G8 -> 31482 | H9: =H7-H8 -> 33370.92 | I9: =I7-I8 -> 35373.175 | J9: =J7-J8 -> 37495.566 | K9: =K7-K8 -> 39745.3
A10: Net Profit | B10: ='Historical Data'!B19 -> 13800 | C10: ='Historical Data'!C19 -> 15150 | D10: ='Historical Data'!D19 -> 17137.5 | E10: ='Historical Data'!E19 -> 19125 | F10: ='Historical Data'!F19 -> 21862.5 | G10: =(G9-$N$10)*(1-$N$7) -> 22458.375 | H10: =(H9-$N$10)*(1-$N$7) -> 23875.065 | I10: =(I9-$N$10)*(1-$N$7) -> 25376.756 | J10: =(J9-$N$10)*(1-$N$7) -> 26968.549 | K10: =(K9-$N$10)*(1-$N$7) -> 28655.85 | M10: Interest Expense | N10: ='Historical Data'!F11*'Historical Data'!B25 -> 1537.5
A11: Cash Flow | B11: =B10+B8 -> 17000 | C11: =C10+C8 -> 18550 | D11: =D10+D8 -> 20837.5 | E11: =E10+E8 -> 23125 | F11: =F10+F8 -> 26162.5 | G11: =G10+G8 -> 27016.375 | H11: =H10+H8 -> 28706.545 | I11: =I10+I8 -> 30498.125 | ... K11: =K10+K8 -> 34410.22

Sheet DCF Valuation
A1: Nexora Technologies Ltd. — DCF Valuation
A3: Particulars | B3: 2025 | C3: 2026 | D3: 2027 | E3: 2028 | F3: 2029
A5: EBIT | B5: ='5 Years Forecast'!G9 -> 31482 | C5: ='5 Years Forecast'!H9 -> 33370.92 | D5: ='5 Years Forecast'!I9 -> 35373.175 | E5: ='5 Years Forecast'!J9 -> 37495.566 | F5: ='5 Years Forecast'!K9 -> 39745.3
A6: Tax Rate | B6: ='5 Years Forecast'!N7 -> 0.25 | C6: =B6 -> 0.25 | D6: =C6 -> 0.25 | E6: =D6 -> 0.25 | F6: =E6 -> 0.25
A7: NOPAT | B7: =B5*(1-B6) -> 23611.5 | C7: =C5*(1-C6) -> 25028.19 | D7: =D5*(1-D6) -> 26529.881 | E7: =E5*(1-E6) -> 28121.674 | F7: =F5*(1-F6) -> 29808.975
A9: Depreciation | B9: ='Financial Analysis'!B6 -> 3200 | C9: ='Financial Analysis'!C6 -> 3400 | D9: ='Financial Analysis'!D6 -> 3700 | E9: ='Financial Analysis'!E6 -> 4000 | F9: ='Financial Analysis'!F6 -> 4300
A10: Capital Expenditure | B10: 0 | C10: 0 | D10: 0 | E10: 0 | F10: 0
A11: Change in Working Capital | B11: 0 | C11: 0 | D11: 0 | E11: 0 | F11: 0
A12: UFCF | B12: =B7+B9-B10-B11 -> 26811.5 | C12: =C7+C9-C10-C11 -> 28428.19 | D12: =D7+D9-D10-D11 -> 30229.881 | E12: =E7+E9-E10-E11 -> 32121.674 | F12: =F7+F9-F10-F11 -> 34108.975
A15: Cost of Equity (CAPM)
A16: Risk Free Rate | B16: ='Historical Data'!$B$22 -> 0.055
A17: Equity Beta | B17: ='Historical Data'!$B$24 -> 1.05
A18: Market Return | B18: ='Historical Data'!$B$23 -> 0.115
A19: Cost of Equity | B19: ='DCF Valuation'!B16+'DCF Valuation'!B17*('DCF Valuation'!B18-'DCF Valuation'!B16) -> 0.118
A21: WACC Calculation
A22: Cost Of Equity | B22: =B19 -> 0.118
A23: Cost Of Debt | B23: ='Historical Data'!B25 -> 0.075
A24: Equity Value | B24: ='Historical Data'!F13 -> 129500
A25: Debt Value | B25: ='Historical Data'!F11 -> 20500
A26: WACC | B26: =B22*(B24/(B24+B25))+B23*(B25/(B24+B25))*(1-'Historical Data'!$B$8) -> 0.10956083
A28: Terminal Value Calculation
A29: 2029 UFCF | B29: =F12 -> 34108.975
A30: Expected Growth Rate | B30: ='Historical Data'!B27 -> 0.06
A31: WACC | B31: =B26 -> 0.10956083
A32: Terminal Value | B32: =B29*(1+B30)/(B31-B30) -> 729517.86
A34: Enterprise Value Calculation
A35: Present Value of Forecast UFCF
A36: Present Value of Terminal Value
A37: Enterprise Value
A38: Discount Factor
A40: Year | B40: 1 | C40: 2 | D40: 3 | E40: 4 | F40: 5
A41: Discount Factor | B41: =1/(1+$B$26)^B40 -> 0.90125748 | C41: =1/(1+$B$26)^C40 -> 0.81226504 | D41: =1/(1+$B$26)^D40 -> 0.73205995 | E41: =1/(1+$B$26)^E40 -> 0.6597745 | F41: =1/(1+$B$26)^F40 -> 0.5946267
A42: PV of UFCF | B42: =B12*B41 -> 24164.065 | C42: =C12*C41 -> 23091.225 | D42: =D12*D41 -> 22130.085 | E42: =E12*E41 -> 21193.062 | F42: =F12*F41 -> 20282.107
A43: PV of Terminal Value | B43: =B32*F41 -> 433790.8
A44: Enterprise Value | B44: =SUM(B42:F42)+B43 -> 544651.35
A46: Equity Value Calculation
A47: Enterprise Value | B47: =B44 -> 544651.35
A48: Less : Debt | B48: ='Historical Data'!F11 -> 20500
A49: ADD : Cash | B49: ='Historical Data'!F12 -> 18500
A50: Equity Value | B50: =B47-B48+B49 -> 542651.35
...

Sheet Chart & Analysis
A1: Nexora Technologies Ltd. — Charts & Analysis
A3: Revenue Growth
A4: Year | B4: Revenue Growth
A5: 2021 | B5: ='Financial Analysis'!C23 -> 0.076923077
A6: 2022 | B6: ='Financial Analysis'!D23 -> 0.095238095
A7: 2023 | B7: ='Financial Analysis'!E23 -> 0.097826087
A8: 2024 | B8: ='Financial Analysis'!F23 -> 0.10891089
A14: Net Profit Growth
A15: Year | B15: Net Profit Growth
A16: 2020 | B16: ='Financial Analysis'!B21 -> 0.17692308
A17: 2021 | B17: ='Financial Analysis'!C21 -> 0.18035714
A18: 2022 | B18: ='Financial Analysis'!D21 -> 0.18627717
A19: 2023 | B19: ='Financial Analysis'!E21 -> 0.18935644
A20: 2024 | B20: ='Financial Analysis'!F21 -> 0.19520089
A29: Ratio Comparison
A30: Ratio | B30: 2020 | C30: 2024
A31: Operating Margin | B31: ='Financial Analysis'!B29 -> 0.28205128 | C31: ='Financial Analysis'!F29 -> 0.30357143
A32: Net Profit Margin | B32: ='Financial Analysis'!B30 -> 0.17692308 | C32: ='Financial Analysis'!F30 -> 0.19520089
A33: ROE | B33: ='Financial Analysis'!B31 -> 0.15333333 | C33: ='Financial Analysis'!F31 -> 0.16882239
A34: Debt To Equity | B34: ='Financial Analysis'!B32 -> 0.16666667 | C34: ='Financial Analysis'!F32 -> 0.15830116
A46: EBITDA Growth
A47: Year | B47: EBITDA Growth
A48: 2021 | B48: ='Financial Analysis'!C25 -> 0.090909091
A49: 2022 | B49: ='Financial Analysis'!D25 -> 0.125
A50: 2023 | B50: ='Financial Analysis'!E25 -> 0.11111111
A51: 2024 | B51: ='Financial Analysis'!F25 -> 0.13333333
A63: Overall Performance
A64: Year | B64: Revenue | C64: EBITDA | D64: Net Profit
A66: 2021 | B66: ='Financial Analysis'!C4 -> 84000 | C66: ='Financial Analysis'!C8 -> 24000 | D66: ='Financial Analysis'!C10 -> 15150
A67: 2022 | B67: ='Financial Analysis'!D4 -> 92000 | C67: ='Financial Analysis'!D8 -> 27000 | D67: ='Financial Analysis'!D10 -> 17137.5
A68: 2023 | B68: ='Financial Analysis'!E4 -> 101000 | C68: ='Financial Analysis'!E8 -> 30000 | D68: ='Financial Analysis'!E10 -> 19125
A69: 2024 | B69: ='Financial Analysis'!F4 -> 112000 | C69: ='Financial Analysis'!F8 -> 34000 | D69: ='Financial Analysis'!F10 -> 21862.5
